Workbook

Sheet Line Items
A1: Invoice No | B1: Invoice Date | C1: Brand / Group | D1: S.No | E1: Item Code | F1: Description | G1: HSN Code | H1: MRP | I1: Qty | J1: Unit | K1: Disc % | L1: Rate | M1: Taxable Amount | N1: CGST % | O1: CGST Amt | P1: SGST % | Q1: SGST Amt | R1: Line Total (Incl. GST) | S1: MRP Value (Gross) | T1: Rate Check | U1: Amount Check | V1: Variance | W1: Flag
A2: 5561GS | B2: 06/03/2026 | C2: GEANARAL | D2: 1 | E2: RT-175 | F2: RMP FORK OIL 175 ML | G2: 85122010 | H2: 45 | I2: 40 | J2: PC | L2: 45 | M2: 1525.42 | N2: 0.09 | O2: 137.29 | P2: 0.09 | Q2: 137.29 | R2: =M2+O2+P2 -> 1662.8 | S2: =H2*I2 -> 1800 | T2: =IF(K2="","",ROUND(H2*(1-K2),2)) | U2: =ROUND(L2*I2/1.18,2) -> 1525.42 | V2: =ROUND(M2-U2,2) -> 0 | W2: =IF(ABS(V2)>0.011,"CHECK","OK") -> OK
A3: 5561GS | B3: 06/03/2026 | C3: NV | D3: 2 | E3: NAJ235 | F3: AIR FILTER PLEASURE | G3: 40169330 | H3: 118 | I3: 5 | J3: PC | K3: 0.43 | L3: 67.26 | M3: 285 | N3: 0.09 | O3: 25.65 | P3: 0.09 | Q3: 25.65 | R3: =M3+O3+P3 -> 310.74 | S3: =H3*I3 -> 590 | T3: =IF(K3="","",ROUND(H3*(1-K3),2)) -> 67.26 | U3: =ROUND(L3*I3/1.18,2) -> 285 | V3: =ROUND(M3-U3,2) -> 0 | W3: =IF(ABS(V3)>0.011,"CHECK","OK") -> OK
A4: 5561GS | B4: 06/03/2026 | C4: NV | D4: 3 | E4: NRM001 | F4: AIR FILTER XL SUPER | G4: 40169330 | H4: 56 | I4: 5 | J4: PC | K4: 0.43 | L4: 31.92 | M4: 135.25 | N4: 0.09 | O4: 12.17 | P4: 0.09 | Q4: 12.17 | R4: =M4+O4+P4 -> 147.51 | S4: =H4*I4 -> 280 | T4: =IF(K4="","",ROUND(H4*(1-K4),2)) -> 31.92 | U4: =ROUND(L4*I4/1.18,2) -> 135.25 | V4: =ROUND(M4-U4,2) -> 0 | W4: =IF(ABS(V4)>0.011,"CHECK","OK") -> OK
A5: 5561GS | B5: 06/03/2026 | C5: FCC | D5: 4 | E5: FCC-016A | F5: HH CLUCH ASSY FCC | G5: 8714 | H5: 726 | I5: 3 | J5: SET | K5: 0.32 | L5: 493.68 | M5: 1255.12 | N5: 0.09 | O5: 112.96 | P5: 0.09 | Q5: 112.96 | R5: =M5+O5+P5 -> 1368.17 | S5: =H5*I5 -> 2178 | T5: =IF(K5="","",ROUND(H5*(1-K5),2)) -> 493.68 | U5: =ROUND(L5*I5/1.18,2) -> 1255.12 | V5: =ROUND(M5-U5,2) -> 0 | W5: =IF(ABS(V5)>0.011,"CHECK","OK") -> OK
A6: 5561GS | B6: 06/03/2026 | C6: FCC | D6: 5 | E6: FCC-125 | F6: GLAMAR CLUTCH ASSY FCC | G6: 8714 | H6: 1575 | I6: 3 | J6: SET | K6: 0.32 | L6: 1071 | M6: 2722.88 | N6: 0.09 | O6: 245.06 | P6: 0.09 | Q6: 245.06 | R6: =M6+O6+P6 -> 2968.03 | S6: =H6*I6 -> 4725 | T6: =IF(K6="","",ROUND(H6*(1-K6),2)) -> 1071 | U6: =ROUND(L6*I6/1.18,2) -> 2722.88 | V6: =ROUND(M6-U6,2) -> 0 | W6: =IF(ABS(V6)>0.011,"CHECK","OK") -> OK
A7: 5561GS | B7: 06/03/2026 | C7: FCC | D7: 6 | E7: FCC-SHI | F7: SHINE CLUTCH ASSY | G7: 87141090 | H7: 1363 | I7: 2 | J7: SET | K7: 0.32 | L7: 926.84 | M7: 1570.92 | N7: 0.09 | O7: 141.38 | P7: 0.09 | Q7: 141.38 | R7: =M7+O7+P7 -> 1712.39 | S7: =H7*I7 -> 2726 | T7: =IF(K7="","",ROUND(H7*(1-K7),2)) -> 926.84 | U7: =ROUND(L7*I7/1.18,2) -> 1570.92 | V7: =ROUND(M7-U7,2) -> 0 | W7: =IF(ABS(V7)>0.011,"CHECK","OK") -> OK
A8: 5561GS | B8: 06/03/2026 | C8: FCC | D8: 7 | E8: FCC-SHI6 | F8: SHINE CLUTCH ASSY BS6 | G8: 87141090 | H8: 1148 | I8: 2 | J8: SET | K8: 0.32 | L8: 780.64 | M8: 1323.12 | N8: 0.09 | O8: 119.08 | P8: 0.09 | Q8: 119.08 | R8: =M8+O8+P8 -> 1442.29 | S8: =H8*I8 -> 2296 | T8: =IF(K8="","",ROUND(H8*(1-K8),2)) -> 780.64 | U8: =ROUND(L8*I8/1.18,2) -> 1323.12 | V8: =ROUND(M8-U8,2) -> 0 | W8: =IF(ABS(V8)>0.011,"CHECK","OK") -> OK
A9: 5561GS | B9: 06/03/2026 | C9: FCC | D9: 8 | E9: FCC-UNI | F9: UNICORN CLUTCH ASSY FCC | G9: 87141090 | H9: 1426 | I9: 1 | J9: SET | K9: 0.32 | L9: 969.68 | M9: 821.76 | N9: 0.09 | O9: 73.96 | P9: 0.09 | Q9: 73.96 | R9: =M9+O9+P9 -> 895.81 | S9: =H9*I9 -> 1426 | T9: =IF(K9="","",ROUND(H9*(1-K9),2)) -> 969.68 | U9: =ROUND(L9*I9/1.18,2) -> 821.76 | V9: =ROUND(M9-U9,2) -> 0 | W9: =IF(ABS(V9)>0.011,"CHECK","OK") -> OK
A10: 5561GS | B10: 06/03/2026 | C10: FCC | D10: 9 | E10: FCC-UNI150 | F10: UNICORN CLUCH ASSY 150 BS6 | G10: 87141090 | H10: 1541 | I10: 2 | J10: SET | K10: 0.32 | L10: 1047.88 | M10: 1776.07 | N10: 0.09 | O10: 159.84 | P10: 0.09 | Q10: 159.84 | R10: =M10+O10+P10 -> 1936 | S10: =H10*I10 -> 3082 | T10: =IF(K10="","",ROUND(H10*(1-K10),2)) -> 1047.88 | U10: =ROUND(L10*I10/1.18,2) -> 1776.07 | V10: =ROUND(M10-U10,2) -> 0 | W10: =IF(ABS(V10)>0.011,"CHECK","OK") -> OK
A11: 5561GS | B11: 06/03/2026 | C11: LUMAX IND | D11: 10 | E11: 216-HLA-DT | F11: H L ASSY HF-DELUXE | G11: 85122010 | H11: 527 | I11: 4 | J11: PC | K11: 0.32 | L11: 358.36 | M11: 1214.78 | N11: 0.09 | O11: 109.33 | P11: 0.09 | Q11: 109.33 | R11: =M11+O11+P11 -> 1324.2 | S11: =H11*I11 -> 2108 | T11: =IF(K11="","",ROUND(H11*(1-K11),2)) -> 358.36 | U11: =ROUND(L11*I11/1.18,2) -> 1214.78 | V11: =ROUND(M11-U11,2) -> 0 | W11: =IF(ABS(V11)>0.011,"CHECK","OK") -> OK
A12: 5561GS | B12: 06/03/2026 | C12: LUMAX IND | D12: 11 | E12: 216-HLA-G | F12: H/L ASSY GLAMOUR | G12: 85122010 | H12: 695 | I12: 1 | K12: 0.32 | L12: 472.6 | M12: 400.51 | N12: 0.09 | O12: 36.04 | P12: 0.09 | Q12: 36.04 | R12: =M12+O12+P12 -> 436.64 | S12: =H12*I12 -> 695 | T12: =IF(K12="","",ROUND(H12*(1-K12),2)) -> 472.6 | U12: =ROUND(L12*I12/1.18,2) -> 400.51 | V12: =ROUND(M12-U12,2) -> 0 | W12: =IF(ABS(V12)>0.011,"CHECK","OK") -> OK
A13: 5561GS | B13: 06/03/2026 | C13: LUMAX IND | D13: 12 | E13: 216-HLA-SP | F13: HL ASSY SPLDR PLUS | G13: 85122010 | H13: 438 | I13: 3 | J13: PC | K13: 0.32 | L13: 297.84 | M13: 757.22 | N13: 0.09 | O13: 68.15 | P13: 0.09 | Q13: 68.15 | R13: =M13+O13+P13 -> 825.46 | S13: =H13*I13 -> 1314 | T13: =IF(K13="","",ROUND(H13*(1-K13),2)) -> 297.84 | U13: =ROUND(L13*I13/1.18,2) -> 757.22 | V13: =ROUND(M13-U13,2) -> 0 | W13: =IF(ABS(V13)>0.011,"CHECK","OK") -> OK
A14: 5561GS | B14: 06/03/2026 | C14: LUMAX IND | D14: 13 | E14: 216-HLU-GF | F14: H L UNIT GLAMR FI O/M | G14: 85122010 | H14: 694 | I14: 2 | J14: PC | K14: 0.32 | L14: 471.92 | M14: 799.86 | N14: 0.09 | O14: 71.99 | P14: 0.09 | Q14: 71.99 | R14: =M14+O14+P14 -> 871.94 | S14: =H14*I14 -> 1388 | T14: =IF(K14="","",ROUND(H14*(1-K14),2)) -> 471.92 | U14: =ROUND(L14*I14/1.18,2) -> 799.86 | V14: =ROUND(M14-U14,2) -> 0 | W14: =IF(ABS(V14)>0.011,"CHECK","OK") -> OK
A15: 5561GS | B15: 06/03/2026 | C15: LUMAX IND | D15: 14 | E15: 216-HLU-XT | F15: CBZ X H L ASSY | G15: 85122010 | H15: 583 | I15: 1 | J15: SET | K15: 0.32 | L15: 396.44 | M15: 335.97 | N15: 0.09 | O15: 30.23 | P15: 0.09 | Q15: 30.23 | R15: =M15+O15+P15 -> 366.29 | S15: =H15*I15 -> 583 | T15: =IF(K15="","",ROUND(H15*(1-K15),2)) -> 396.44 | U15: =ROUND(L15*I15/1.18,2) -> 335.97 | V15: =ROUND(M15-U15,2) -> 0 | W15: =IF(ABS(V15)>0.011,"CHECK","OK") -> OK
A16: 5561GS | B16: 06/03/2026 | C16: LUMAX IND | D16: 15 | E16: 216-HLU-N | F16: H/L ASSY PASSION PLUS | G16: 85122010 | H16: 445 | I16: 4 | J16: PC | K16: 0.32 | L16: 302.6 | M16: 1025.76 | N16: 0.09 | O16: 92.32 | P16: 0.09 | Q16: 92.32 | R16: =M16+O16+P16 -> 1118.17 | S16: =H16*I16 -> 1780 | T16: =IF(K16="","",ROUND(H16*(1-K16),2)) -> 302.6 | U16: =ROUND(L16*I16/1.18,2) -> 1025.76 | V16: =ROUND(M16-U16,2) -> 0 | W16: =IF(ABS(V16)>0.011,"CHECK","OK") -> OK
A17: 5561GS | B17: 06/03/2026 | C17: LUMAX IND | D17: 16 | E17: 224-BLA-XL | F17: IND SET XL SUPER FR LONG STAY | G17: 85122010 | H17: 194 | I17: 10 | J17: SET | K17: 0.35 | L17: 126.1 | M17: 1068.64 | N17: 0.09 | O17: 96.18 | P17: 0.09 | Q17: 96.18 | R17: =M17+O17+P17 -> 1164.91 | S17: =H17*I17 -> 1940 | T17: =IF(K17="","",ROUND(H17*(1-K17),2)) -> 126.1 | U17: =ROUND(L17*I17/1.18,2) -> 1068.64 | V17: =ROUND(M17-U17,2) -> 0 | W17: =IF(ABS(V17)>0.011,"CHECK","OK") -> OK
A18: 5561GS | B18: 06/03/2026 | C18: LUMAX IND | D18: 17 | E18: 224-BLA-XL | F18: IND SET XL REAR | G18: 85122010 | H18: 184 | I18: 10 | J18: ST | K18: 0.35 | L18: 119.6 | M18: 1013.56 | N18: 0.09 | O18: 91.22 | P18: 0.09 | Q18: 91.22 | R18: =M18+O18+P18 -> 1104.87 | S18: =H18*I18 -> 1840 | T18: =IF(K18="","",ROUND(H18*(1-K18),2)) -> 119.6 | U18: =ROUND(L18*I18/1.18,2) -> 1013.56 | V18: =ROUND(M18-U18,2) -> 0 | W18: =IF(ABS(V18)>0.011,"CHECK","OK") -> OK
A19: 5561GS | B19: 06/03/2026 | C19: LUMAX IND | D19: 18 | E19: 225-HLU-AC | F19: ACCESS H L UNIT 125CC N/M | G19: 85122010 | H19: 598 | I19: 1 | J19: PC | K19: 0.32 | L19: 406.64 | M19: 344.61 | N19: 0.09 | O19: 31.01 | P19: 0.09 | Q19: 31.01 | R19: =M19+O19+P19 -> 375.71 | S19: =H19*I19 -> 598 | T19: =IF(K19="","",ROUND(H19*(1-K19),2)) -> 406.64 | U19: =ROUND(L19*I19/1.18,2) -> 344.61 | V19: =ROUND(M19-U19,2) -> 0 | W19: =IF(ABS(V19)>0.011,"CHECK","OK") -> OK
A20: 5561GS | B20: 06/03/2026 | C20: LUMAX IND | D20: 19 | E20: 225-HLU-AC | F20: ACCESS H L UNIT 125CC N/M | G20: 85122010 | H20: 598 | I20: 1 | J20: PC | K20: 0.32 | L20: 406.64 | M20: 344.61 | N20: 0.09 | O20: 31.01 | P20: 0.09 | Q20: 31.01 | R20: =M20+O20+P20 -> 375.71 | S20: =H20*I20 -> 598 | T20: =IF(K20="","",ROUND(H20*(1-K20),2)) -> 406.64 | U20: =ROUND(L20*I20/1.18,2) -> 344.61 | V20: =ROUND(M20-U20,2) -> 0 | W20: =IF(ABS(V20)>0.011,"CHECK","OK") -> OK
A21: 5561GS | B21: 06/03/2026 | C21: LUMAX IND | D21: 20 | E21: 225-HLUA | F21: ACCESS H L ASSY | G21: 85122010 | H21: 568 | I21: 2 | J21: PC | K21: 0.32 | L21: 386.24 | M21: 654.64 | N21: 0.09 | O21: 58.92 | P21: 0.09 | Q21: 58.92 | R21: =M21+O21+P21 -> 713.65 | S21: =H21*I21 -> 1136 | T21: =IF(K21="","",ROUND(H21*(1-K21),2)) -> 386.24 | U21: =ROUND(L21*I21/1.18,2) -> 654.64 | V21: =ROUND(M21-U21,2) -> 0 | W21: =IF(ABS(V21)>0.011,"CHECK","OK") -> OK
A22: 5561GS | B22: 06/03/2026 | C22: LUMAX IND | D22: 21 | E22: 238-HLU-UN | F22: UNICORON HL ASYY NEW | G22: 85122010 | H22: 899 | I22: 2 | J22: PC | K22: 0.32 | L22: 611.32 | M22: 1036.14 | N22: 0.09 | O22: 93.25 | P22: 0.09 | Q22: 93.25 | R22: =M22+O22+P22 -> 1129.48 | S22: =H22*I22 -> 1798 | T22: =IF(K22="","",ROUND(H22*(1-K22),2)) -> 611.32 | U22: =ROUND(L22*I22/1.18,2) -> 1036.14 | V22: =ROUND(M22-U22,2) -> 0 | W22: =IF(ABS(V22)>0.011,"CHECK","OK") -> OK
A23: 5561GS | B23: 06/03/2026 | C23: LUMAX IND | D23: 22 | E23: 239-HLA-5G | F23: ACTIVA 5G H L ASSY | G23: 85122010 | H23: 1835 | I23: 2 | J23: SET | K23: 0.32 | L23: 1247.8 | M23: 2114.92 | N23: 0.09 | O23: 190.34 | P23: 0.09 | Q23: 190.34 | R23: =M23+O23+P23 -> 2305.35 | S23: =H23*I23 -> 3670 | T23: =IF(K23="","",ROUND(H23*(1-K23),2)) -> 1247.8 | U23: =ROUND(L23*I23/1.18,2) -> 2114.92 | V23: =ROUND(M23-U23,2) -> 0 | W23: =IF(ABS(V23)>0.011,"CHECK","OK") -> OK
A24: 5561GS | B24: 06/03/2026 | C24: LUMAX IND | D24: 23 | E24: 239-HLA-6G | F24: HEAD LIGHT ASSY ACTIVA 6G | G24: 85122010 | H24: 556 | I24: 2 | J24: PC | K24: 0.32 | L24: 378.08 | M24: 640.81 | N24: 0.09 | O24: 57.67 | P24: 0.09 | Q24: 57.67 | R24: =M24+O24+P24 -> 698.57 | S24: =H24*I24 -> 1112 | T24: =IF(K24="","",ROUND(H24*(1-K24),2)) -> 378.08 | U24: =ROUND(L24*I24/1.18,2) -> 640.81 | V24: =ROUND(M24-U24,2) -> 0 | W24: =IF(ABS(V24)>0.011,"CHECK","OK") -> OK
... A27: 5561GS | B27: 06/03/2026 | C27: LUMAX IND | D27: 26 | E27: 248-HLA-UG | F27: PULSAR UG3 H L ASSY | G27: 85122010 | H27: 1011 | I27: 2 | J27: PC | K27: 0.32 | L27: 687.48 | M27: 1165.22 | N27: 0.09 | O27: 104.87 | P27: 0.09 | Q27: 104.87 | R27: =M27+O27+P27 -> 1270.18 | S27: =H27*I27 -> 2022 | T27: =IF(K27="","",ROUND(H27*(1-K27),2)) -> 687.48 | U27: =ROUND(L27*I27/1.18,2) -> 1165.22 | V27: =ROUND(M27-U27,2) -> 0 | W27: =IF(ABS(V27)>0.011,"CHECK","OK") -> OK
A28: 5561GS | B28: 06/03/2026 | C28: LUMAX IND | D28: 27 | E28: 254-HLUD | F28: PLATINA H L ASSY | G28: 85122010 | H28: 577 | I28: 2 | K28: 0.32 | L28: 392.36 | M28: 665.02 | N28: 0.09 | O28: 59.85 | P28: 0.09 | Q28: 59.85 | R28: =M28+O28+P28 -> 724.96 | S28: =H28*I28 -> 1154 | T28: =IF(K28="","",ROUND(H28*(1-K28),2)) -> 392.36 | U28: =ROUND(L28*I28/1.18,2) -> 665.02 | V28: =ROUND(M28-U28,2) -> 0 | W28: =IF(ABS(V28)>0.011,"CHECK","OK") -> OK
A29: 5561GS | B29: 06/03/2026 | C29: LUMAX IND | D29: 28 | E29: 260-HLU-HS | F29: H/L UNIT SHINE N\M WT PARKING | G29: 85122010 | H29: 800 | I29: 2 | J29: PC | K29: 0.32 | L29: 544 | M29: 922.03 | N29: 0.09 | O29: 82.98 | P29: 0.09 | Q29: 82.98 | R29: =M29+O29+P29 -> 1005.1 | S29: =H29*I29 -> 1600 | T29: =IF(K29="","",ROUND(H29*(1-K29),2)) -> 544 | U29: =ROUND(L29*I29/1.18,2) -> 922.03 | V29: =ROUND(M29-U29,2) -> 0 | W29: =IF(ABS(V29)>0.011,"CHECK","OK") -> OK
A30: 5561GS | B30: 06/03/2026 | C30: LUMAX IND | D30: 29 | E30: 260-HLUD | F30: SHINE H L ASSY | G30: 85122010 | H30: 608 | I30: 2 | J30: SET | K30: 0.32 | L30: 413.44 | M30: 700.75 | N30: 0.09 | O30: 63.06 | P30: 0.09 | Q30: 63.06 | R30: =M30+O30+P30 -> 763.9 | S30: =H30*I30 -> 1216 | T30: =IF(K30="","",ROUND(H30*(1-K30),2)) -> 413.44 | U30: =ROUND(L30*I30/1.18,2) -> 700.75 | V30: =ROUND(M30-U30,2) -> 0 | W30: =IF(ABS(V30)>0.011,"CHECK","OK") -> OK
A31: 5561GS | B31: 06/03/2026 | C31: GABRIEL OIL | D31: 30 | E31: GM-FF34011 | F31: FORK OIL 350 ML | G31: 27101980 | H31: 98 | I31: 10 | J31: PC | L31: 98 | M31: 830.51 | N31: 0.09 | O31: 74.74 | P31: 0.09 | Q31: 74.74 | R31: =M31+O31+P31 -> 905.34 | S31: =H31*I31 -> 980 | T31: =IF(K31="","",ROUND(H31*(1-K31),2)) | U31: =ROUND(L31*I31/1.18,2) -> 830.51 | V31: =ROUND(M31-U31,2) -> 0 | W31: =IF(ABS(V31)>0.011,"CHECK","OK") -> OK
A32: 5563GS | B32: 06/03/2026 | C32: SAI | D32: 1 | E32: SAI-03 | F32: UNICORN FF BLACK | G32: 87141090 | H32: 490 | I32: 2 | J32: PC | K32: 0.38 | L32: 303.8 | M32: 514.92 | N32: 0.09 | O32: 46.34 | P32: 0.09 | Q32: 46.34 | R32: =M32+O32+P32 -> 561.35 | S32: =H32*I32 -> 980 | T32: =IF(K32="","",ROUND(H32*(1-K32),2)) -> 303.8 | U32: =ROUND(L32*I32/1.18,2) -> 514.92 | V32: =ROUND(M32-U32,2) -> 0 | W32: =IF(ABS(V32)>0.011,"CHECK","OK") -> OK
A33: 5563GS | B33: 06/03/2026 | C33: SAI | D33: 2 | E33: SAI-102 | F33: SIDE COVER SPLENDER PLUS BLACK(BLUE) | G33: 87141090 | H33: 550 | I33: 2 | J33: SET | K33: 0.38 | L33: 341 | M33: 577.97 | N33: 0.09 | O33: 52.01 | P33: 0.09 | Q33: 52.01 | R33: =M33+O33+P33 -> 630.07 | S33: =H33*I33 -> 1100 | T33: =IF(K33="","",ROUND(H33*(1-K33),2)) -> 341 | U33: =ROUND(L33*I33/1.18,2) -> 577.97 | V33: =ROUND(M33-U33,2) -> 0 | W33: =IF(ABS(V33)>0.011,"CHECK","OK") -> OK
A34: 5563GS | B34: 06/03/2026 | C34: SAI | D34: 3 | E34: SAI-120 | F34: FRONT FENDER SHINE BLACK | G34: 87141090 | H34: 475 | I34: 4 | J34: PC | K34: 0.38 | L34: 294.5 | M34: 998.31 | N34: 0.09 | O34: 89.84 | P34: 0.09 | Q34: 89.84 | R34: =M34+O34+P34 -> 1088.24 | S34: =H34*I34 -> 1900 | T34: =IF(K34="","",ROUND(H34*(1-K34),2)) -> 294.5 | U34: =ROUND(L34*I34/1.18,2) -> 998.31 | V34: =ROUND(M34-U34,2) -> 0 | W34: =IF(ABS(V34)>0.011,"CHECK","OK") -> OK
A35: 5563GS | B35: 06/03/2026 | C35: SAI | D35: 4 | E35: SAI-131 | F35: REAR COWL SPLENDER+ BLACK(BLUE) | G35: 87141090 | H35: 460 | I35: 2 | J35: SET | K35: 0.38 | L35: 285.2 | M35: 483.39 | N35: 0.09 | O35: 43.5 | P35: 0.09 | Q35: 43.5 | R35: =M35+O35+P35 -> 526.98 | S35: =H35*I35 -> 920 | T35: =IF(K35="","",ROUND(H35*(1-K35),2)) -> 285.2 | U35: =ROUND(L35*I35/1.18,2) -> 483.39 | V35: =ROUND(M35-U35,2) -> 0 | W35: =IF(ABS(V35)>0.011,"CHECK","OK") -> OK
A36: 5563GS | B36: 06/03/2026 | C36: SAI | D36: 5 | E36: SAI-131I | F36: REAR COWL SPLENDER PLUS BLACK (SILVER) | G36: 87141090 | H36: 460 | I36: 2 | J36: SET | K36: 0.38 | L36: 285.2 | M36: 483.39 | N36: 0.09 | O36: 43.5 | P36: 0.09 | Q36: 43.5 | R36: =M36+O36+P36 -> 526.98 | S36: =H36*I36 -> 920 | T36: =IF(K36="","",ROUND(H36*(1-K36),2)) -> 285.2 | U36: =ROUND(L36*I36/1.18,2) -> 483.39 | V36: =ROUND(M36-U36,2) -> 0 | W36: =IF(ABS(V36)>0.011,"CHECK","OK") -> OK
A37: 5563GS | B37: 06/03/2026 | C37: SAI | D37: 6 | E37: SAI-132 | F37: SIDE COVER SPLENDER PLUS NM BLACK(BL) | G37: 87141090 | H37: 535 | I37: 2 | J37: SET | K37: 0.38 | L37: 331.7 | M37: 562.2 | N37: 0.09 | O37: 50.6 | P37: 0.09 | Q37: 50.6 | R37: =M37+O37+P37 -> 612.89 | S37: =H37*I37 -> 1070 | T37: =IF(K37="","",ROUND(H37*(1-K37),2)) -> 331.7 | U37: =ROUND(L37*I37/1.18,2) -> 562.2 | V37: =ROUND(M37-U37,2) -> 0 | W37: =IF(ABS(V37)>0.011,"CHECK","OK") -> OK
A38: 5563GS | B38: 06/03/2026 | C38: SAI | D38: 7 | E38: SAI-132I | F38: SPLENDOR PLUS BLACK/SILVER SIDE DOOR | G38: 87141090 | H38: 535 | I38: 2 | J38: SET | K38: 0.38 | L38: 331.7 | M38: 562.2 | N38: 0.09 | O38: 50.6 | P38: 0.09 | Q38: 50.6 | R38: =M38+O38+P38 -> 612.89 | S38: =H38*I38 -> 1070 | T38: =IF(K38="","",ROUND(H38*(1-K38),2)) -> 331.7 | U38: =ROUND(L38*I38/1.18,2) -> 562.2 | V38: =ROUND(M38-U38,2) -> 0 | W38: =IF(ABS(V38)>0.011,"CHECK","OK") -> OK
A39: 5563GS | B39: 06/03/2026 | C39: SAI | D39: 8 | E39: SAI-14 | F39: CBZ X BLACK FF | G39: 87141090 | H39: 565 | I39: 2 | J39: PC | K39: 0.38 | L39: 350.3 | M39: 593.73 | N39: 0.09 | O39: 53.43 | P39: 0.09 | Q39: 53.43 | R39: =M39+O39+P39 -> 647.25 | S39: =H39*I39 -> 1130 | T39: =IF(K39="","",ROUND(H39*(1-K39),2)) -> 350.3 | U39: =ROUND(L39*I39/1.18,2) -> 593.73 | V39: =ROUND(M39-U39,2) -> 0 | W39: =IF(ABS(V39)>0.011,"CHECK","OK") -> OK
A40: 5563GS | B40: 06/03/2026 | C40: SAI | D40: 9 | E40: SAI-157 | F40: HLV SHINE LATEST BLACK RED STICKER | G40: 87141090 | H40: 590 | I40: 3 | J40: SET | K40: 0.38 | L40: 365.8 | M40: 930 | N40: 0.09 | O40: 83.7 | P40: 0.09 | Q40: 83.7 | R40: =M40+O40+P40 -> 1013.79 | S40: =H40*I40 -> 1770 | T40: =IF(K40="","",ROUND(H40*(1-K40),2)) -> 365.8 | U40: =ROUND(L40*I40/1.18,2) -> 930 | V40: =ROUND(M40-U40,2) -> 0 | W40: =IF(ABS(V40)>0.011,"CHECK","OK") -> OK
A41: 5563GS | B41: 06/03/2026 | C41: SAI | D41: 10 | E41: SAI-159 | F41: HLV PASSION PRO BLACK (RED STICKERS) | G41: 87141090 | H41: 740 | I41: 4 | J41: SET | K41: 0.38 | L41: 458.8 | M41: 1555.25 | N41: 0.09 | O41: 139.97 | P41: 0.09 | Q41: 139.97 | R41: =M41+O41+P41 -> 1695.31 | S41: =H41*I41 -> 2960 | T41: =IF(K41="","",ROUND(H41*(1-K41),2)) -> 458.8 | U41: =ROUND(L41*I41/1.18,2) -> 1555.25 | V41: =ROUND(M41-U41,2) -> 0 | W41: =IF(ABS(V41)>0.011,"CHECK","OK") -> OK
A42: 5563GS | B42: 06/03/2026 | C42: SAI | D42: 11 | E42: SAI-159A | F42: HLV PASSION PRO BLACK (BLUE STICKERS) | G42: 87141090 | H42: 740 | I42: 4 | J42: PC | K42: 0.38 | L42: 458.8 | M42: 1555.25 | N42: 0.09 | O42: 139.97 | P42: 0.09 | Q42: 139.97 | R42: =M42+O42+P42 -> 1695.31 | S42: =H42*I42 -> 2960 | T42: =IF(K42="","",ROUND(H42*(1-K42),2)) -> 458.8 | U42: =ROUND(L42*I42/1.18,2) -> 1555.25 | V42: =ROUND(M42-U42,2) -> 0 | W42: =IF(ABS(V42)>0.011,"CHECK","OK") -> OK
...

Sheet Invoice Summary
A1: Invoice Summary — Kumar Auto Stores
A3: Supplier | B3: KUMAR AUTO STORES, D.No.4-18/1 Garagaparru Road, Bhimavaram-534202
A4: Supplier GSTIN | B4: 37AITPG4383P1ZB
A5: Buyer | B5: SRI SRI SATYA SAI AUTMOBILE AGENC, 2-12-27/1 Railway Station Road, Tadepalligudem-534101
A6: Buyer GSTIN | B6: 37CUJPG4763K1Z5
A7: Invoice Date (all 3) | B7: 06/03/2026 (DD/MM/YYYY = 6 March 2026)
A8: Source | B8: Adobe_Scan_30_Aug_2026.pdf — 10 scanned pages
A10: Invoice No | B10: Lines | C10: Total Qty | D10: Taxable Amount (computed) | E10: Taxable (printed) | F10: CGST (printed) | G10: SGST (printed) | H10: Rounding Off | I10: Net Amount (computed) | J10: Net Amount (printed) | K10: Variance
A11: 5561GS | B11: =COUNTIFS('Line Items'!$A$2:$A$226,$A11) -> 30 | C11: =SUMIFS('Line Items'!$I$2:$I$226,'Line Items'!$A$2:$A$226,$A11) -> 130 | D11: =ROUND(SUMIFS('Line Items'!$M$2:$M$226,'Line Items'!$A$2:$A$226,$A11),2) -> 28641.68 | E11: 28641.68 | F11: 2577.75 | G11: 2577.75 | H11: -0.18 | I11: =ROUND(E11+F11+G11+H11,2) -> 33797 | J11: 33797 | K11: =ROUND(D11-E11,2) -> 0
A12: 5563GS | B12: =COUNTIFS('Line Items'!$A$2:$A$226,$A12) -> 94 | C12: =SUMIFS('Line Items'!$I$2:$I$226,'Line Items'!$A$2:$A$226,$A12) -> 282 | D12: =ROUND(SUMIFS('Line Items'!$M$2:$M$226,'Line Items'!$A$2:$A$226,$A12),2) -> 88074.15 | E12: 88074.15 | F12: 7926.67 | G12: 7926.67 | H12: -0.49 | I12: =ROUND(E12+F12+G12+H12,2) -> 103927 | J12: 103927 | K12: =ROUND(D12-E12,2) -> 0
A13: 5559GS | B13: =COUNTIFS('Line Items'!$A$2:$A$226,$A13) -> 101 | C13: =SUMIFS('Line Items'!$I$2:$I$226,'Line Items'!$A$2:$A$226,$A13) -> 1379 | D13: =ROUND(SUMIFS('Line Items'!$M$2:$M$226,'Line Items'!$A$2:$A$226,$A13),2) -> 67789.41 | E13: 67789.41 | F13: 6101.05 | G13: 6101.05 | H13: 0.49 | I13: =ROUND(E13+F13+G13+H13,2) -> 79992 | J13: 79992 | K13: =ROUND(D13-E13,2) -> 0
A14: TOTAL | B14: =SUM(B11:B13) -> 225 | C14: =SUM(C11:C13) -> 1791 | D14: =SUM(D11:D13) -> 184505.24 | E14: =SUM(E11:E13) -> 184505.24 | F14: =SUM(F11:F13) -> 16605.47 | G14: =SUM(G11:G13) -> 16605.47 | H14: =SUM(H11:H13) -> -0.18 | I14: =SUM(I11:I13) -> 217716 | ... K14: =SUM(K11:K13) -> 0

Sheet Brand Summary
A1: Brand / Group Totals — reconciled to printed invoice subtotals
A3: Invoice No | B3: Brand / Group | C3: Lines | D3: Qty | E3: Gross (MRP Value) computed | F3: Gross printed on invoice | G3: Net (Taxable) computed | H3: Net printed on invoice | I3: Gross Var | J3: Net Var | K3: Reconciles?
A4: 5561GS | B4: GEANARAL | C4: =COUNTIFS('Line Items'!$A$2:$A$226,$A4,'Line Items'!$C$2:$C$226,$B4) -> 1 | D4: =SUMIFS('Line Items'!$I$2:$I$226,'Line Items'!$A$2:$A$226,$A4,'Line Items'!$C$2:$C$226,$B4) -> 40 | E4: =ROUND(SUMIFS('Line Items'!$S$2:$S$226,'Line Items'!$A$2:$A$226,$A4,'Line Items'!$C$2:$C$226,$B4),2) -> 1800 | F4: 1800 | G4: =ROUND(SUMIFS('Line Items'!$M$2:$M$226,'Line Items'!$A$2:$A$226,$A4,'Line Items'!$C$2:$C$226,$B4),2) -> 1525.42 | H4: 1525.42 | I4: =ROUND(E4-F4,2) -> 0 | J4: =ROUND(G4-H4,2) -> 0 | K4: =IF(AND(ABS(I4)<0.02,ABS(J4)<0.02),"YES","CHECK") -> YES
A5: 5561GS | B5: NV | C5: =COUNTIFS('Line Items'!$A$2:$A$226,$A5,'Line Items'!$C$2:$C$226,$B5) -> 2 | D5: =SUMIFS('Line Items'!$I$2:$I$226,'Line Items'!$A$2:$A$226,$A5,'Line Items'!$C$2:$C$226,$B5) -> 10 | E5: =ROUND(SUMIFS('Line Items'!$S$2:$S$226,'Line Items'!$A$2:$A$226,$A5,'Line Items'!$C$2:$C$226,$B5),2) -> 870 | F5: 870 | G5: =ROUND(SUMIFS('Line Items'!$M$2:$M$226,'Line Items'!$A$2:$A$226,$A5,'Line Items'!$C$2:$C$226,$B5),2) -> 420.25 | H5: 420.25 | I5: =ROUND(E5-F5,2) -> 0 | J5: =ROUND(G5-H5,2) -> 0 | K5: =IF(AND(ABS(I5)<0.02,ABS(J5)<0.02),"YES","CHECK") -> YES
A6: 5561GS | B6: FCC | C6: =COUNTIFS('Line Items'!$A$2:$A$226,$A6,'Line Items'!$C$2:$C$226,$B6) -> 6 | D6: =SUMIFS('Line Items'!$I$2:$I$226,'Line Items'!$A$2:$A$226,$A6,'Line Items'!$C$2:$C$226,$B6) -> 13 | E6: =ROUND(SUMIFS('Line Items'!$S$2:$S$226,'Line Items'!$A$2:$A$226,$A6,'Line Items'!$C$2:$C$226,$B6),2) -> 16433 | F6: 16433 | G6: =ROUND(SUMIFS('Line Items'!$M$2:$M$226,'Line Items'!$A$2:$A$226,$A6,'Line Items'!$C$2:$C$226,$B6),2) -> 9469.87 | H6: 9469.87 | I6: =ROUND(E6-F6,2) -> 0 | J6: =ROUND(G6-H6,2) -> 0 | K6: =IF(AND(ABS(I6)<0.02,ABS(J6)<0.02),"YES","CHECK") -> YES
A7: 5561GS | B7: LUMAX IND | C7: =COUNTIFS('Line Items'!$A$2:$A$226,$A7,'Line Items'!$C$2:$C$226,$B7) -> 20 | D7: =SUMIFS('Line Items'!$I$2:$I$226,'Line Items'!$A$2:$A$226,$A7,'Line Items'!$C$2:$C$226,$B7) -> 57 | E7: =ROUND(SUMIFS('Line Items'!$S$2:$S$226,'Line Items'!$A$2:$A$226,$A7,'Line Items'!$C$2:$C$226,$B7),2) -> 28618 | F7: 28618 | G7: =ROUND(SUMIFS('Line Items'!$M$2:$M$226,'Line Items'!$A$2:$A$226,$A7,'Line Items'!$C$2:$C$226,$B7),2) -> 16395.63 | H7: 16395.63 | I7: =ROUND(E7-F7,2) -> 0 | J7: =ROUND(G7-H7,2) -> 0 | K7: =IF(AND(ABS(I7)<0.02,ABS(J7)<0.02),"YES","CHECK") -> YES
A8: 5561GS | B8: GABRIEL OIL | C8: =COUNTIFS('Line Items'!$A$2:$A$226,$A8,'Line Items'!$C$2:$C$226,$B8) -> 1 | D8: =SUMIFS('Line Items'!$I$2:$I$226,'Line Items'!$A$2:$A$226,$A8,'Line Items'!$C$2:$C$226,$B8) -> 10 | E8: =ROUND(SUMIFS('Line Items'!$S$2:$S$226,'Line Items'!$A$2:$A$226,$A8,'Line Items'!$C$2:$C$226,$B8),2) -> 980 | F8: 980 | G8: =ROUND(SUMIFS('Line Items'!$M$2:$M$226,'Line Items'!$A$2:$A$226,$A8,'Line Items'!$C$2:$C$226,$B8),2) -> 830.51 | H8: 830.51 | I8: =ROUND(E8-F8,2) -> 0 | J8: =ROUND(G8-H8,2) -> 0 | K8: =IF(AND(ABS(I8)<0.02,ABS(J8)<0.02),"YES","CHECK") -> YES
A9: 5563GS | B9: SAI | C9: =COUNTIFS('Line Items'!$A$2:$A$226,$A9,'Line Items'!$C$2:$C$226,$B9) -> 94 | D9: =SUMIFS('Line Items'!$I$2:$I$226,'Line Items'!$A$2:$A$226,$A9,'Line Items'!$C$2:$C$226,$B9) -> 282 | E9: =ROUND(SUMIFS('Line Items'!$S$2:$S$226,'Line Items'!$A$2:$A$226,$A9,'Line Items'!$C$2:$C$226,$B9),2) -> 167625 | F9: 167625 | G9: =ROUND(SUMIFS('Line Items'!$M$2:$M$226,'Line Items'!$A$2:$A$226,$A9,'Line Items'!$C$2:$C$226,$B9),2) -> 88074.15 | H9: 88074.15 | I9: =ROUND(E9-F9,2) -> 0 | J9: =ROUND(G9-H9,2) -> 0 | K9: =IF(AND(ABS(I9)<0.02,ABS(J9)<0.02),"YES","CHECK") -> YES
A10: 5559GS | B10: SLD | C10: =COUNTIFS('Line Items'!$A$2:$A$226,$A10,'Line Items'!$C$2:$C$226,$B10) -> 2 | D10: =SUMIFS('Line Items'!$I$2:$I$226,'Line Items'!$A$2:$A$226,$A10,'Line Items'!$C$2:$C$226,$B10) -> 4 | E10: =ROUND(SUMIFS('Line Items'!$S$2:$S$226,'Line Items'!$A$2:$A$226,$A10,'Line Items'!$C$2:$C$226,$B10),2) -> 4476 | F10: 4476 | G10: =ROUND(SUMIFS('Line Items'!$M$2:$M$226,'Line Items'!$A$2:$A$226,$A10,'Line Items'!$C$2:$C$226,$B10),2) -> 2465.59 | H10: 2465.59 | I10: =ROUND(E10-F10,2) -> 0 | J10: =ROUND(G10-H10,2) -> 0 | K10: =IF(AND(ABS(I10)<0.02,ABS(J10)<0.02),"YES","CHECK") -> YES
A11: 5559GS | B11: BODIX | C11: =COUNTIFS('Line Items'!$A$2:$A$226,$A11,'Line Items'!$C$2:$C$226,$B11) -> 1 | D11: =SUMIFS('Line Items'!$I$2:$I$226,'Line Items'!$A$2:$A$226,$A11,'Line Items'!$C$2:$C$226,$B11) -> 2 | E11: =ROUND(SUMIFS('Line Items'!$S$2:$S$226,'Line Items'!$A$2:$A$226,$A11,'Line Items'!$C$2:$C$226,$B11),2) -> 678 | F11: 678 | G11: =ROUND(SUMIFS('Line Items'!$M$2:$M$226,'Line Items'!$A$2:$A$226,$A11,'Line Items'!$C$2:$C$226,$B11),2) -> 316.02 | H11: 316.02 | I11: =ROUND(E11-F11,2) -> 0 | J11: =ROUND(G11-H11,2) -> 0 | K11: =IF(AND(ABS(I11)<0.02,ABS(J11)<0.02),"YES","CHECK") -> YES
A12: 5559GS | B12: HTA | C12: =COUNTIFS('Line Items'!$A$2:$A$226,$A12,'Line Items'!$C$2:$C$226,$B12) -> 16 | D12: =SUMIFS('Line Items'!$I$2:$I$226,'Line Items'!$A$2:$A$226,$A12,'Line Items'!$C$2:$C$226,$B12) -> 150 | E12: =ROUND(SUMIFS('Line Items'!$S$2:$S$226,'Line Items'!$A$2:$A$226,$A12,'Line Items'!$C$2:$C$226,$B12),2) -> 9200 | F12: 9200 | G12: =ROUND(SUMIFS('Line Items'!$M$2:$M$226,'Line Items'!$A$2:$A$226,$A12,'Line Items'!$C$2:$C$226,$B12),2) -> 5022.02 | H12: 5022.02 | I12: =ROUND(E12-F12,2) -> 0 | J12: =ROUND(G12-H12,2) -> 0 | K12: =IF(AND(ABS(I12)<0.02,ABS(J12)<0.02),"YES","CHECK") -> YES
A13: 5559GS | B13: ANL | C13: =COUNTIFS('Line Items'!$A$2:$A$226,$A13,'Line Items'!$C$2:$C$226,$B13) -> 9 | D13: =SUMIFS('Line Items'!$I$2:$I$226,'Line Items'!$A$2:$A$226,$A13,'Line Items'!$C$2:$C$226,$B13) -> 105 | E13: =ROUND(SUMIFS('Line Items'!$S$2:$S$226,'Line Items'!$A$2:$A$226,$A13,'Line Items'!$C$2:$C$226,$B13),2) -> 23090 | F13: 23090 | G13: =ROUND(SUMIFS('Line Items'!$M$2:$M$226,'Line Items'!$A$2:$A$226,$A13,'Line Items'!$C$2:$C$226,$B13),2) -> 10370.93 | H13: 10370.93 | I13: =ROUND(E13-F13,2) -> 0 | J13: =ROUND(G13-H13,2) -> 0 | K13: =IF(AND(ABS(I13)<0.02,ABS(J13)<0.02),"YES","CHECK") -> YES
A14: 5559GS | B14: ACCURAT | C14: =COUNTIFS('Line Items'!$A$2:$A$226,$A14,'Line Items'!$C$2:$C$226,$B14) -> 4 | D14: =SUMIFS('Line Items'!$I$2:$I$226,'Line Items'!$A$2:$A$226,$A14,'Line Items'!$C$2:$C$226,$B14) -> 155 | E14: =ROUND(SUMIFS('Line Items'!$S$2:$S$226,'Line Items'!$A$2:$A$226,$A14,'Line Items'!$C$2:$C$226,$B14),2) -> 974.5 | F14: 974.5 | G14: =ROUND(SUMIFS('Line Items'!$M$2:$M$226,'Line Items'!$A$2:$A$226,$A14,'Line Items'!$C$2:$C$226,$B14),2) -> 454.22 | H14: 454.22 | I14: =ROUND(E14-F14,2) -> 0 | J14: =ROUND(G14-H14,2) -> 0 | K14: =IF(AND(ABS(I14)<0.02,ABS(J14)<0.02),"YES","CHECK") -> YES
A15: 5559GS | B15: NV | C15: =COUNTIFS('Line Items'!$A$2:$A$226,$A15,'Line Items'!$C$2:$C$226,$B15) -> 21 | D15: =SUMIFS('Line Items'!$I$2:$I$226,'Line Items'!$A$2:$A$226,$A15,'Line Items'!$C$2:$C$226,$B15) -> 567 | E15: =ROUND(SUMIFS('Line Items'!$S$2:$S$226,'Line Items'!$A$2:$A$226,$A15,'Line Items'!$C$2:$C$226,$B15),2) -> 7157.2 | F15: 7157.2 | G15: =ROUND(SUMIFS('Line Items'!$M$2:$M$226,'Line Items'!$A$2:$A$226,$A15,'Line Items'!$C$2:$C$226,$B15),2) -> 3457.28 | H15: 3457.28 | I15: =ROUND(E15-F15,2) -> 0 | J15: =ROUND(G15-H15,2) -> 0 | K15: =IF(AND(ABS(I15)<0.02,ABS(J15)<0.02),"YES","CHECK") -> YES
... A21: 5559GS | B21: CAMP NET | C21: =COUNTIFS('Line Items'!$A$2:$A$226,$A21,'Line Items'!$C$2:$C$226,$B21) -> 1 | D21: =SUMIFS('Line Items'!$I$2:$I$226,'Line Items'!$A$2:$A$226,$A21,'Line Items'!$C$2:$C$226,$B21) -> 10 | E21: =ROUND(SUMIFS('Line Items'!$S$2:$S$226,'Line Items'!$A$2:$A$226,$A21,'Line Items'!$C$2:$C$226,$B21),2) -> 1050 | F21: 1050 | G21: =ROUND(SUMIFS('Line Items'!$M$2:$M$226,'Line Items'!$A$2:$A$226,$A21,'Line Items'!$C$2:$C$226,$B21),2) -> 889.83 | H21: 889.83 | I21: =ROUND(E21-F21,2) -> 0 | J21: =ROUND(G21-H21,2) -> 0 | K21: =IF(AND(ABS(I21)<0.02,ABS(J21)<0.02),"YES","CHECK") -> YES
B22: TOTAL | C22: =SUM(C4:C21) -> 225 | D22: =SUM(D4:D21) -> 1791 | E22: =SUM(E4:E21) -> 344978.7 | F22: =SUM(F4:F21) -> 344978.7 | G22: =SUM(G4:G21) -> 184505.24 | H22: =SUM(H4:H21) -> 184505.24

Sheet Notes
B1: Notes, Assumptions & Data-Quality Log
B3: 1. Source and extraction method
B4: Extracted from Adobe_Scan_30_Aug_2026.pdf (10 pages) — a skewed dot-matrix printout with no usable text layer.
B5: Pages were rendered at 400 dpi, deskewed, and OCR'd. Raw OCR misaligned the Rate column against MRP by a full
B6: row on several pages, so every line was independently verified against the arithmetic the invoice itself enforces:
B7: Rate = MRP x (1 - Disc%) Taxable Amount = Rate x Qty / 1.18 CGST = SGST = 9% of Taxable Amount
B8: All 225 lines were then reconciled against every printed brand-group Gross/Net subtotal, every page brought-forward,
B9: and each invoice footer. All 18 brand-group subtotals, all 3 quantity counts and all 3 subtotals match exactly.
B11: 2. Colour legend
B12: Blue text = transcribed exactly as printed on the invoice (source data).
B13: Black text = calculated by formula in this workbook. Never overwrite a black cell; edit the blue inputs instead.
B14: Column W ('Flag') on Line Items reads CHECK where the printed amount differs from Rate x Qty / 1.18 by > 0.01.
... B44: All three invoices are intra-state (both parties GSTIN 37...), taxed at CGST 9% + SGST 9% = 18%.
